public class ExceptionTest02 
{
	//Field
	private int sum;
	private int avg;

	public ExceptionTest02() {
	}

	public void sum(int x, int y) {
		System.out.println("1. ==> sum 시작");
		sum = x + y;
		System.out.println("1. ==> 합 : "+sum);
		System.out.println("1. ==> sum 끝");
	}

	public void avg(int z) {
		System.out.println("2. ==> avg 시작");
		//try-catch로 JVM에서 던지는 Exception 객체를 처리하장
		//==> 출력결과를 확인하기

		try {
			avg = sum /z;	
		} catch (ArithmeticException e) {
			System.out.println("1.>>========================");
			System.out.println("z값이 0인 모양입니다. 나누기 불가");
			System.out.println("2.>>========================");
			System.out.println(e); //e.toString()
			System.out.println("3.>>========================");
			e.printStackTrace();
			System.out.println("4.>>========================");
		}
		
		System.out.println("2. ==> 평귱 :"+avg );
		System.out.println("2. ==> avg 끝");
	}

	public static void main(String[] args) 
	{
		int i = Integer.parseInt(args[0]);
		int j = Integer.parseInt(args[1]);
		int k = Integer.parseInt(args[2]);

		ExceptionTest01 et = new ExceptionTest01();
		et.sum(i,j);
		et.avg(k);

		System.out.println("main Method End...");

	}
}
